Workbook
Name aporte: APP!$D$17
Name patrimonio: APP!$D$20
Name qtd_anos: APP!$D$18
Name rendimento_carteira: APP!$D$13
Name salario: APP!$D$12
Name sugestao_investimento: APP!$D$14
Name taxa_mensal: APP!$D$19

Sheet APP
B1: Simulador de Investimentos em Fundos Imobiliários
B2: Ferramenta educacional para estimar patrimônio, dividendos mensais e distribuição de aportes por perfil de investidor.
B11: CONFIGURAÇÕES
B12: Salário | D12: 2000
B13: Rendimento Carteira | D13: 0.006
B14: Sugestão de Investimento (30%) | D14: =D12*30% -> 600
B16: INVESTIMENTO MENSAL
B17: Quanto investir por mês ? | D17: 200
B18: Por Quantos Anos ? | D18: 5
B19: Taxa de Rendimento mensal ? | D19: 0.01079
B20: Patrimônio acumulado ? | D20: =FV(taxa_mensal,qtd_anos*12,aporte*-1) -> 16755.383
B21: Dividendos Mensais ? | D21: =patrimonio*rendimento_carteira -> 100.5323
B23: Cenários | D23: Dividendo
A24: 2 | B24: Quanto em 2 Anos ? | C24: =FV($D$19,$A24*12,$D$17*-1) -> 5445.5255 | D24: =C24*rendimento_carteira -> 32.673153
A25: 5 | B25: Quanto em 5 Anos ? | C25: =FV($D$19,$A25*12,$D$17*-1) -> 16755.383 | D25: =C25*rendimento_carteira -> 100.5323
A26: 10 | B26: Quanto em 10 Anos ? | C26: =FV($D$19,$A26*12,$D$17*-1) -> 48656.843 | D26: =C26*rendimento_carteira -> 291.94106
A27: 20 | B27: Quanto em 20 Anos ? | C27: =FV($D$19,$A27*12,$D$17*-1) -> 225039.68 | D27: =C27*rendimento_carteira -> 1350.2381
A28: 30 | B28: Quanto em 30 Anos ? | C28: =FV($D$19,$A28*12,$D$17*-1) -> 864433.93 | D28: =C28*rendimento_carteira -> 5186.6036
B32: PERFIL | C32: Moderado
B33: VALOR A SER INVESTIDO POR MÊS | C33: =aporte -> 200
B35: TIPO DE FII | C35: Percentual Sugerido | D35: Valores
B36: PAPEL | C36: =VLOOKUP($C$32&"-"&B36,Planilha2!$A:$D,4,FALSE) -> 0.32 | D36: =C36*$C$33 -> 64
B37: TIJOLO | C37: =VLOOKUP($C$32&"-"&B37,Planilha2!$A:$D,4,FALSE) -> 0.35 | D37: =C37*$C$33 -> 70
B38: HÍBRIDOS | C38: =VLOOKUP($C$32&"-"&B38,Planilha2!$A:$D,4,FALSE) -> 0.08 | D38: =C38*$C$33 -> 16
B39: FOFs | C39: =VLOOKUP($C$32&"-"&B39,Planilha2!$A:$D,4,FALSE) -> 0.05 | D39: =C39*$C$33 -> 10
B40: DESENVOLVIMENTO | C40: =VLOOKUP($C$32&"-"&B40,Planilha2!$A:$D,4,FALSE) -> 0.1 | D40: =C40*$C$33 -> 20
B41: HOTELARIAS | C41: =VLOOKUP($C$32&"-"&B41,Planilha2!$A:$D,4,FALSE) -> 0.1 | D41: =C41*$C$33 -> 20
D42: =SUM(D36:D41) -> 200

Sheet Dashboard
A1: Dashboard Executivo — Simulador de FIIs
A3: Resumo da Simulação
A4: Investimento mensal | B4: =APP!D17 -> 200 | C4: Prazo (anos) | D4: =APP!D18 -> 5
A5: Taxa mensal | B5: =APP!D19 -> 0.01079 | C5: Rendimento carteira | D5: =APP!D13 -> 0.006
A6: Patrimônio estimado | B6: =APP!D20 -> 16755.383 | C6: Dividendos mensais | D6: =APP!D21 -> 100.5323
A7: Total investido | B7: =APP!D17*APP!D18*12 -> 12000 | C7: Ganho estimado | D7: =APP!D20-(APP!D17*APP!D18*12) -> 4755.3828
A8: Perfil do investidor | B8: =APP!C32 -> Moderado | C8: Sugestão 30% salário | D8: =APP!D14 -> 600
A10: Com base nos parâmetros informados, investindo R$ 200,00 por mês durante 5 anos, com taxa mensal de 1,08%, o patrimônio estimado será de aproximadamente R$ 16.755,38 e os dividendos mensais estimados serão de R$ 100,53.
A14: Ano | B14: Patrimônio acumulado | C14: Dividendos mensais | E14: Tipo de FII | F14: % sugerido | G14: Valor mensal
A15: =APP!A24 -> 2 | B15: =APP!C24 -> 5445.5255 | C15: =APP!D24 -> 32.673153 | E15: =APP!B36 -> PAPEL | F15: =APP!C36 -> 0.32 | G15: =APP!D36 -> 64
A16: =APP!A25 -> 5 | B16: =APP!C25 -> 16755.383 | C16: =APP!D25 -> 100.5323 | E16: =APP!B37 -> TIJOLO | F16: =APP!C37 -> 0.35 | G16: =APP!D37 -> 70
A17: =APP!A26 -> 10 | B17: =APP!C26 -> 48656.843 | C17: =APP!D26 -> 291.94106 | E17: =APP!B38 -> HÍBRIDOS | F17: =APP!C38 -> 0.08 | G17: =APP!D38 -> 16
A18: =APP!A27 -> 20 | B18: =APP!C27 -> 225039.68 | C18: =APP!D27 -> 1350.2381 | E18: =APP!B39 -> FOFs | F18: =APP!C39 -> 0.05 | G18: =APP!D39 -> 10
A19: =APP!A28 -> 30 | B19: =APP!C28 -> 864433.93 | C19: =APP!D28 -> 5186.6036 | E19: =APP!B40 -> DESENVOLVIMENTO | F19: =APP!C40 -> 0.1 | G19: =APP!D40 -> 20
E20: =APP!B41 -> HOTELARIAS | F20: =APP!C41 -> 0.1 | G20: =APP!D41 -> 20
A23: Ano | B23: Total investido | C23: Patrimônio projetado
A24: 1 | B24: =APP!D17*A24*12 -> 2400 | C24: =FV(APP!D19,A24*12,APP!D17*-1) -> 2547.6772
A25: 2 | B25: =APP!D17*A25*12 -> 4800 | C25: =FV(APP!D19,A25*12,APP!D17*-1) -> 5445.5255
A26: 3 | B26: =APP!D17*A26*12 -> 7200 | C26: =FV(APP!D19,A26*12,APP!D17*-1) -> 8741.6748
A27: 4 | B27: =APP!D17*A27*12 -> 9600 | C27: =FV(APP!D19,A27*12,APP!D17*-1) -> 12490.871
A28: 5 | B28: =APP!D17*A28*12 -> 12000 | C28: =FV(APP!D19,A28*12,APP!D17*-1) -> 16755.383
A29: 6 | B29: =APP!D17*A29*12 -> 14400 | C29: =FV(APP!D19,A29*12,APP!D17*-1) -> 21606.04
A30: 7 | B30: =APP!D17*A30*12 -> 16800 | C30: =FV(APP!D19,A30*12,APP!D17*-1) -> 27123.407
A31: 8 | B31: =APP!D17*A31*12 -> 19200 | C31: =FV(APP!D19,A31*12,APP!D17*-1) -> 33399.12
A32: 9 | B32: =APP!D17*A32*12 -> 21600 | C32: =FV(APP!D19,A32*12,APP!D17*-1) -> 40537.412
A33: 10 | B33: =APP!D17*A33*12 -> 24000 | C33: =FV(APP!D19,A33*12,APP!D17*-1) -> 48656.843
A34: 11 | B34: =APP!D17*A34*12 -> 26400 | C34: =FV(APP!D19,A34*12,APP!D17*-1) -> 57892.266
A35: 12 | B35: =APP!D17*A35*12 -> 28800 | C35: =FV(APP!D19,A35*12,APP!D17*-1) -> 68397.072
A36: 13 | B36: =APP!D17*A36*12 -> 31200 | C36: =FV(APP!D19,A36*12,APP!D17*-1) -> 80345.734
A37: 14 | B37: =APP!D17*A37*12 -> 33600 | C37: =FV(APP!D19,A37*12,APP!D17*-1) -> 93936.706
A38: 15 | B38: =APP!D17*A38*12 -> 36000 | C38: =FV(APP!D19,A38*12,APP!D17*-1) -> 109395.72
A39: 16 | B39: =APP!D17*A39*12 -> 38400 | C39: =FV(APP!D19,A39*12,APP!D17*-1) -> 126979.53
A40: 17 | B40: =APP!D17*A40*12 -> 40800 | C40: =FV(APP!D19,A40*12,APP!D17*-1) -> 146980.19
A41: 18 | B41: =APP!D17*A41*12 -> 43200 | C41: =FV(APP!D19,A41*12,APP!D17*-1) -> 169729.88
A42: 19 | B42: =APP!D17*A42*12 -> 45600 | C42: =FV(APP!D19,A42*12,APP!D17*-1) -> 195606.45
A43: 20 | B43: =APP!D17*A43*12 -> 48000 | C43: =FV(APP!D19,A43*12,APP!D17*-1) -> 225039.68
A44: 21 | B44: =APP!D17*A44*12 -> 50400 | C44: =FV(APP!D19,A44*12,APP!D17*-1) -> 258518.43
A45: 22 | B45: =APP!D17*A45*12 -> 52800 | C45: =FV(APP!D19,A45*12,APP!D17*-1) -> 296598.74
A46: 23 | B46: =APP!D17*A46*12 -> 55200 | C46: =FV(APP!D19,A46*12,APP!D17*-1) -> 339913.07
A47: 24 | B47: =APP!D17*A47*12 -> 57600 | C47: =FV(APP!D19,A47*12,APP!D17*-1) -> 389180.85
...

Sheet Metodologia
A1: Metodologia e Documentação do Simulador
A3: Objetivo
A4: Criar uma ferramenta em Excel para simular investimentos mensais em Fundos Imobiliários, estimando patrimônio acumulado, dividendos mensais e cenários de longo prazo.
A7: Variável | B7: Local | C7: Tipo | D7: Descrição
A8: Salário | B8: APP!D12 | C8: Entrada | D8: Base para sugestão de investimento de 30%.
A9: Rendimento da carteira | B9: APP!D13 | C9: Premissa | D9: Percentual usado para estimar dividendos mensais.
A10: Investimento mensal | B10: APP!D17 | C10: Entrada | D10: Valor aportado mensalmente pelo usuário.
A11: Prazo em anos | B11: APP!D18 | C11: Entrada | D11: Quantidade de anos da simulação.
A12: Taxa de rendimento mensal | B12: APP!D19 | C12: Entrada | D12: Taxa usada para projetar patrimônio acumulado.
A13: Perfil do investidor | B13: APP!C32 | C13: Entrada | D13: Perfil usado para sugerir a composição dos FIIs.
A14: Patrimônio acumulado | B14: APP!D20 | C14: Resultado | D14: Projeção calculada com valor futuro.
A15: Dividendos mensais | B15: APP!D21 | C15: Resultado | D15: Estimativa calculada sobre o patrimônio acumulado.
A17: Fórmulas principais
A18: Patrimônio acumulado | B18: =FV(taxa_mensal,qtd_anos*12,aporte*-1)
A19: Dividendos mensais | B19: =patrimonio*rendimento_carteira
A20: Cenários | B20: =FV($D$19,anos*12,$D$17*-1)
A21: Distribuição por perfil | B21: =VLOOKUP(perfil&tipo, tabela de percentuais, 4, FALSE)
A22: Total investido | B22: =aporte mensal*prazo*12
A24: Premissas e limitações
A25: 1. O modelo considera aportes mensais constantes e taxa de rendimento mensal fixa.
A26: 2. Os dividendos são estimados com base no patrimônio projetado e no rendimento da carteira.
A27: 3. Custos, impostos, inflação, vacância e variações reais de mercado não estão incluídos.
A28: 4. A ferramenta é educacional e não representa recomendação de investimento.
A29: 5. Fonte conceitual: desafio DIO — Simulador de Investimentos em Fundos Imobiliários com Excel.

Sheet Planilha2
A2: CHAVE | B2: PERFIL | C2: TIPO DE FII | D2: %
A3: =B3&"-"&C3 -> Conservador-PAPEL | B3: Conservador | C3: PAPEL | D3: 0.3 | H3: %
A4: =B4&"-"&C4 -> Conservador-TIJOLO | B4: Conservador | C4: TIJOLO | D4: 0.5 | G4: Moderado-TIJOLO | H4: =VLOOKUP(G4,$A:$D,4,FALSE) -> 0.35
A5: =B5&"-"&C5 -> Conservador-HÍBRIDOS | B5: Conservador | C5: HÍBRIDOS | D5: 0.1
A6: =B6&"-"&C6 -> Conservador-FOFs | B6: Conservador | C6: FOFs | D6: 0.1
A7: =B7&"-"&C7 -> Conservador-DESENVOLVIMENTO | B7: Conservador | C7: DESENVOLVIMENTO | D7: 0
A8: =B8&"-"&C8 -> Conservador-HOTELARIAS | B8: Conservador | C8: HOTELARIAS | D8: 0
A9: =B9&"-"&C9 -> Moderado-PAPEL | B9: Moderado | C9: PAPEL | D9: 0.32
A10: =B10&"-"&C10 -> Moderado-TIJOLO | B10: Moderado | C10: TIJOLO | D10: 0.35
A11: =B11&"-"&C11 -> Moderado-HÍBRIDOS | B11: Moderado | C11: HÍBRIDOS | D11: 0.08
A12: =B12&"-"&C12 -> Moderado-FOFs | B12: Moderado | C12: FOFs | D12: 0.05
A13: =B13&"-"&C13 -> Moderado-DESENVOLVIMENTO | B13: Moderado | C13: DESENVOLVIMENTO | D13: 0.1
A14: =B14&"-"&C14 -> Moderado-HOTELARIAS | B14: Moderado | C14: HOTELARIAS | D14: 0.1
A15: =B15&"-"&C15 -> Agressivo-PAPEL | B15: Agressivo | C15: PAPEL | D15: 0.5
A16: =B16&"-"&C16 -> Agressivo-TIJOLO | B16: Agressivo | C16: TIJOLO | D16: 0.1
... A20: =B20&"-"&C20 -> Agressivo-HOTELARIAS | B20: Agressivo | C20: HOTELARIAS | D20: 0.1
